<?xml version="1.0" encoding="utf-8"?>
<!-- =================================================================================== -->
<!-- |    This document was autogenerated by xacro from mybot.xacro                    | -->
<!-- |    EDITING THIS FILE BY HAND IS NOT RECOMMENDED                                 | -->
<!-- =================================================================================== -->
<robot name="mybot" xmlns:xacro="http://www.ros.org/wiki/xacro">
  <!-- First ROS-Gazebo robot -->
  <!-- For more information about Gazebo extensions, see http://gazebosim.org/tutorials?tut=ros_gzplugins -->
  <!-- ########################################### -->
  <!-- 						 -->
  <!-- ########################################### -->
  <gazebo reference="chassis">
    <material>Gazebo/Orange</material>
  </gazebo>
  <!-- ########################################### -->
  <!-- Set the collision flag for the arm          -->
  <!-- ########################################### -->
  <gazebo reference="link1">
    <selfCollide>true</selfCollide>
  </gazebo>
  <gazebo reference="link2">
    <selfCollide>true</selfCollide>
  </gazebo>
  <gazebo reference="link3">
    <selfCollide>true</selfCollide>
  </gazebo>
  <gazebo reference="link4">
    <selfCollide>true</selfCollide>
  </gazebo>
  <gazebo reference="link5">
    <selfCollide>true</selfCollide>
  </gazebo>
  <!-- ########################################### -->
  <!-- Define the friction coefficient for the caster "wheel" -->
  <!-- ########################################### -->
  <gazebo reference="caster_wheel">
    <mu1>0.0</mu1>
    <mu2>0.0</mu2>
    <material>Gazebo/Red</material>
  </gazebo>
  <!-- ########################################### -->
  <!--                                             -->
  <!-- ########################################### -->
  <gazebo>
    <plugin filename="libgazebo_ros_control.so" name="gazebo_ros_control">
      <robotNamespace>/mybot</robotNamespace>
    </plugin>
  </gazebo>
  <!-- ########################################### -->
  <!-- Configure the differential drive controller -->
  <!-- The robot can be driven manually using command: 
$ rosrun turtlesim turtle_teleop_key /turtle1/cmd_vel:=/mybot/cmd_vel -->
  <!-- ########################################### -->
  <gazebo>
    <plugin filename="libgazebo_ros_diff_drive.so" name="differential_drive_controller">
      <alwaysOn>true</alwaysOn>
      <updateRate>100</updateRate>
      <leftJoint>left_wheel_hinge</leftJoint>
      <rightJoint>right_wheel_hinge</rightJoint>
      <wheelSeparation>0.45</wheelSeparation>
      <wheelDiameter>0.15</wheelDiameter>
      <torque>20</torque>
      <commandTopic>mybot/cmd_vel</commandTopic>
      <odometryTopic>mybot/odom_diffdrive</odometryTopic>
      <odometryFrame>odom</odometryFrame>
      <robotBaseFrame>footprint</robotBaseFrame>
    </plugin>
  </gazebo>
  <!-- #################### -->
  <!-- Configure the camera -->
  <!-- #################### -->
  <gazebo reference="camera">
    <material>Gazebo/Blue</material>
    <sensor name="camera1" type="camera">
      <update_rate>30.0</update_rate>
      <camera name="head">
        <horizontal_fov>1.3962634</horizontal_fov>
        <image>
          <width>800</width>
          <height>800</height>
          <format>R8G8B8</format>
        </image>
        <clip>
          <near>0.02</near>
          <far>300</far>
        </clip>
      </camera>
      <plugin filename="libgazebo_ros_camera.so" name="camera_controller">
        <alwaysOn>true</alwaysOn>
        <updateRate>0.0</updateRate>
        <cameraName>mybot/camera1</cameraName>
        <imageTopicName>image_raw</imageTopicName>
        <cameraInfoTopicName>camera_info</cameraInfoTopicName>
        <frameName>camera</frameName>
        <hackBaseline>0.07</hackBaseline>
        <distortionK1>0.0</distortionK1>
        <distortionK2>0.0</distortionK2>
        <distortionK3>0.0</distortionK3>
        <distortionT1>0.0</distortionT1>
        <distortionT2>0.0</distortionT2>
      </plugin>
    </sensor>
  </gazebo>
  <!-- Put here the robot description -->
  <material name="black">
    <color rgba="0.0 0.0 0.0 1.0"/>
  </material>
  <material name="blue">
    <color rgba="0.0 0.0 0.8 1.0"/>
  </material>
  <material name="green">
    <color rgba="0.0 0.8 0.0 1.0"/>
  </material>
  <material name="grey">
    <color rgba="0.2 0.2 0.2 1.0"/>
  </material>
  <material name="orange">
    <color rgba="1.0 0.423529411765 0.0392156862745 1.0"/>
  </material>
  <material name="brown">
    <color rgba="0.870588235294 0.811764705882 0.764705882353 1.0"/>
  </material>
  <material name="red">
    <color rgba="0.8 0.0 0.0 1.0"/>
  </material>
  <material name="white">
    <color rgba="1.0 1.0 1.0 1.0"/>
  </material>
  <!-- Put here the robot description -->
  <link name="footprint"/>
  <joint name="base_joint" type="fixed">
    <parent link="footprint"/>
    <child link="chassis"/>
  </joint>
  <link name="chassis">
    <collision>
      <origin rpy="0 0 0" xyz="0 0 0.075"/>
      <geometry>
        <cylinder length="0.5" radius="0.2"/>
      </geometry>
    </collision>
    <visual>
      <origin rpy="0 0 0" xyz="0 0 0.075"/>
      <geometry>
        <cylinder length="0.5" radius="0.2"/>
      </geometry>
      <material name="orange"/>
    </visual>
    <inertial>
      <origin rpy="0 0 0" xyz="0 0 0.075"/>
      <mass value="50"/>
      <inertia ixx="1.54166666667" ixy="0" ixz="0" iyy="1.54166666667" iyz="0" izz="1.0"/>
    </inertial>
  </link>
  <joint name="fixed" type="fixed">
    <parent link="chassis"/>
    <child link="caster_wheel"/>
  </joint>
  <link name="caster_wheel">
    <collision>
      <origin rpy="0 0 0" xyz="-0.1 0 -0.15"/>
      <geometry>
        <sphere radius="0.1"/>
      </geometry>
    </collision>
    <visual>
      <origin rpy="0 0 0" xyz="-0.1 0 -0.15"/>
      <geometry>
        <sphere radius="0.1"/>
      </geometry>
      <material name="red"/>
    </visual>
    <inertial>
      <origin rpy="0 0 0" xyz="-0.1 0 -0.35"/>
      <mass value="5"/>
      <inertia ixx="0.02" ixy="0" ixz="0" iyy="0.02" iyz="0" izz="0.02"/>
    </inertial>
  </link>
  <link name="left_wheel">
    <collision>
      <origin rpy="0 1.57079632679 1.57079632679" xyz="0 0 0"/>
      <geometry>
        <cylinder length="0.05" radius="0.075"/>
      </geometry>
    </collision>
    <visual>
      <origin rpy="0 1.57079632679 1.57079632679" xyz="0 0 0"/>
      <geometry>
        <cylinder length="0.05" radius="0.075"/>
      </geometry>
      <material name="black"/>
    </visual>
    <inertial>
      <origin rpy="0 1.57079632679 1.57079632679" xyz="0 0 0"/>
      <mass value="5"/>
      <inertia ixx="0.00807291666667" ixy="0" ixz="0" iyy="0.00807291666667" iyz="0" izz="0.0140625"/>
    </inertial>
  </link>
  <gazebo reference="left_wheel">
    <mu1 value="1.0"/>
    <mu2 value="1.0"/>
    <kp value="10000000.0"/>
    <kd value="1.0"/>
    <fdir1 value="1 0 0"/>
    <material>Gazebo/Black</material>
  </gazebo>
  <joint name="left_wheel_hinge" type="continuous">
    <parent link="chassis"/>
    <child link="left_wheel"/>
    <origin rpy="0 0 0" xyz="0.15 0.225 -0.175"/>
    <axis rpy="0 0 0" xyz="0 1 0"/>
    <limit effort="100" velocity="100"/>
    <joint_properties damping="0.0" friction="0.0"/>
  </joint>
  <transmission name="left_trans">
    <type>transmission_interface/SimpleTransmission</type>
    <joint name="left_wheel_hinge">
      <hardwareInterface>EffortJointInterface</hardwareInterface>
    </joint>
    <actuator name="leftMotor">
      <hardwareInterface>EffortJointInterface</hardwareInterface>
      <mechanicalReduction>100</mechanicalReduction>
    </actuator>
  </transmission>
  <link name="right_wheel">
    <collision>
      <origin rpy="0 1.57079632679 1.57079632679" xyz="0 0 0"/>
      <geometry>
        <cylinder length="0.05" radius="0.075"/>
      </geometry>
    </collision>
    <visual>
      <origin rpy="0 1.57079632679 1.57079632679" xyz="0 0 0"/>
      <geometry>
        <cylinder length="0.05" radius="0.075"/>
      </geometry>
      <material name="black"/>
    </visual>
    <inertial>
      <origin rpy="0 1.57079632679 1.57079632679" xyz="0 0 0"/>
      <mass value="5"/>
      <inertia ixx="0.00807291666667" ixy="0" ixz="0" iyy="0.00807291666667" iyz="0" izz="0.0140625"/>
    </inertial>
  </link>
  <gazebo reference="right_wheel">
    <mu1 value="1.0"/>
    <mu2 value="1.0"/>
    <kp value="10000000.0"/>
    <kd value="1.0"/>
    <fdir1 value="1 0 0"/>
    <material>Gazebo/Black</material>
  </gazebo>
  <joint name="right_wheel_hinge" type="continuous">
    <parent link="chassis"/>
    <child link="right_wheel"/>
    <origin rpy="0 0 0" xyz="0.15 -0.225 -0.175"/>
    <axis rpy="0 0 0" xyz="0 1 0"/>
    <limit effort="100" velocity="100"/>
    <joint_properties damping="0.0" friction="0.0"/>
  </joint>
  <transmission name="right_trans">
    <type>transmission_interface/SimpleTransmission</type>
    <joint name="right_wheel_hinge">
      <hardwareInterface>EffortJointInterface</hardwareInterface>
    </joint>
    <actuator name="rightMotor">
      <hardwareInterface>EffortJointInterface</hardwareInterface>
      <mechanicalReduction>100</mechanicalReduction>
    </actuator>
  </transmission>
  <!-- ************************* -->
  <!--            ARM            -->
  <!-- ************************* -->
  <link name="link0">
    <visual>
      <origin rpy="0 0 0" xyz="0.0 0.0 0.0"/>
      <geometry>
        <box size="0.04 0.02 0.036"/>
      </geometry>
      <material name="green"/>
    </visual>
    <collision>
      <origin rpy="0 0 0" xyz="0.0 0.0 0.0"/>
      <geometry>
        <box size="0.04 0.02 0.036"/>
      </geometry>
    </collision>
    <visual>
      <origin rpy="0 0 0" xyz="0.01 0.0 0.022"/>
      <geometry>
        <cylinder length="0.008" radius="0.001"/>
      </geometry>
      <material name="green"/>
    </visual>
    <inertial>
      <origin rpy="0 0 0" xyz="0.0 0.0 0.0"/>
      <mass value="0.05"/>
      <inertia ixx="7.06666666667e-06" ixy="0" ixz="0" iyy="1.20666666667e-05" iyz="0" izz="1.20666666667e-05"/>
    </inertial>
  </link>
  <!-- A "transmission" defines the relation between and actuator and a joint. See http://wiki.ros.org/urdf/XML/Transmission-->
  <transmission name="link0_trans">
    <type>transmission_interface/SimpleTransmission</type>
    <joint name="link0_joint">
      <hardwareInterface>EffortJointInterface</hardwareInterface>
    </joint>
    <actuator name="link0_motor">
      <hardwareInterface>EffortJointInterface</hardwareInterface>
      <mechanicalReduction>100</mechanicalReduction>
    </actuator>
  </transmission>
  <link name="link1">
    <visual>
      <origin rpy="0 0 0" xyz="0.0 0.0 0.0"/>
      <geometry>
        <box size="0.04 0.02 0.036"/>
      </geometry>
      <material name="green"/>
    </visual>
    <collision>
      <origin rpy="0 0 0" xyz="0.0 0.0 0.0"/>
      <geometry>
        <box size="0.04 0.02 0.036"/>
      </geometry>
    </collision>
    <visual>
      <origin rpy="0 0 0" xyz="0.01 0.0 0.022"/>
      <geometry>
        <cylinder length="0.008" radius="0.001"/>
      </geometry>
      <material name="green"/>
    </visual>
    <inertial>
      <origin rpy="0 0 0" xyz="0.0 0.0 0.0"/>
      <mass value="0.05"/>
      <inertia ixx="7.06666666667e-06" ixy="0" ixz="0" iyy="1.20666666667e-05" iyz="0" izz="1.20666666667e-05"/>
    </inertial>
  </link>
  <!-- A "transmission" defines the relation between and actuator and a joint. See http://wiki.ros.org/urdf/XML/Transmission-->
  <transmission name="link1_trans">
    <type>transmission_interface/SimpleTransmission</type>
    <joint name="link1_joint">
      <hardwareInterface>EffortJointInterface</hardwareInterface>
    </joint>
    <actuator name="link1_motor">
      <hardwareInterface>EffortJointInterface</hardwareInterface>
      <mechanicalReduction>100</mechanicalReduction>
    </actuator>
  </transmission>
  <link name="link2">
    <visual>
      <origin rpy="0.00 0.00 0.00" xyz="-0.035 0.0 -0.018"/>
      <geometry>
        <box size="0.090  0.010 0.001"/>
      </geometry>
      <material name="red"/>
    </visual>
    <visual>
      <origin rpy="0.00 0.00 0.00" xyz="-0.035 0.00 0.018"/>
      <geometry>
        <box size="0.090 0.010 0.001"/>
      </geometry>
      <material name="red"/>
    </visual>
    <inertial>
      <mass value="0.05"/>
      <inertia ixx="0.04" ixy="0.00" ixz="0.00" iyy="0.04" iyz="0.00" izz="0.02"/>
    </inertial>
  </link>
  <link name="link3">
    <visual>
      <origin rpy="0 0 0" xyz="-0.01 0.0 0.0"/>
      <geometry>
        <box size="0.04 0.02 0.036"/>
      </geometry>
      <material name="green"/>
    </visual>
    <collision>
      <origin rpy="0 0 0" xyz="-0.01 0.0 0.0"/>
      <geometry>
        <box size="0.04 0.02 0.036"/>
      </geometry>
    </collision>
    <visual>
      <origin rpy="0 0 0" xyz="0.0 0.0 0.022"/>
      <geometry>
        <cylinder length="0.008" radius="0.001"/>
      </geometry>
      <material name="green"/>
    </visual>
    <inertial>
      <origin rpy="0 0 0" xyz="-0.01 0.0 0.0"/>
      <mass value="0.05"/>
      <inertia ixx="7.06666666667e-06" ixy="0" ixz="0" iyy="1.20666666667e-05" iyz="0" izz="1.20666666667e-05"/>
    </inertial>
  </link>
  <!-- A "transmission" defines the relation between and actuator and a joint. See http://wiki.ros.org/urdf/XML/Transmission-->
  <transmission name="link3_trans">
    <type>transmission_interface/SimpleTransmission</type>
    <joint name="link3_joint">
      <hardwareInterface>EffortJointInterface</hardwareInterface>
    </joint>
    <actuator name="link3_motor">
      <hardwareInterface>EffortJointInterface</hardwareInterface>
      <mechanicalReduction>100</mechanicalReduction>
    </actuator>
  </transmission>
  <link name="link4">
    <visual>
      <origin rpy="0.00 0.00 0.00" xyz="-0.035 0.0 -0.018"/>
      <geometry>
        <box size="0.090  0.010 0.001"/>
      </geometry>
      <material name="red"/>
    </visual>
    <visual>
      <origin rpy="0.00 0.00 0.00" xyz="-0.035 0.00 0.018"/>
      <geometry>
        <box size="0.090 0.010 0.001"/>
      </geometry>
      <material name="red"/>
    </visual>
    <inertial>
      <mass value="0.05"/>
      <inertia ixx="0.04" ixy="0.00" ixz="0.00" iyy="0.04" iyz="0.00" izz="0.02"/>
    </inertial>
  </link>
  <link name="link5">
    <visual>
      <origin rpy="0 0 0" xyz="-0.01 0.0 0.0"/>
      <geometry>
        <box size="0.04 0.02 0.036"/>
      </geometry>
      <material name="green"/>
    </visual>
    <collision>
      <origin rpy="0 0 0" xyz="-0.01 0.0 0.0"/>
      <geometry>
        <box size="0.04 0.02 0.036"/>
      </geometry>
    </collision>
    <visual>
      <origin rpy="0 0 0" xyz="0.0 0.0 0.022"/>
      <geometry>
        <cylinder length="0.008" radius="0.001"/>
      </geometry>
      <material name="green"/>
    </visual>
    <inertial>
      <origin rpy="0 0 0" xyz="-0.01 0.0 0.0"/>
      <mass value="0.05"/>
      <inertia ixx="7.06666666667e-06" ixy="0" ixz="0" iyy="1.20666666667e-05" iyz="0" izz="1.20666666667e-05"/>
    </inertial>
  </link>
  <!-- A "transmission" defines the relation between and actuator and a joint. See http://wiki.ros.org/urdf/XML/Transmission-->
  <transmission name="link5_trans">
    <type>transmission_interface/SimpleTransmission</type>
    <joint name="link5_joint">
      <hardwareInterface>EffortJointInterface</hardwareInterface>
    </joint>
    <actuator name="link5_motor">
      <hardwareInterface>EffortJointInterface</hardwareInterface>
      <mechanicalReduction>100</mechanicalReduction>
    </actuator>
  </transmission>
  <joint name="chassis_arm" type="fixed">
    <parent link="chassis"/>
    <child link="link0"/>
    <origin rpy="0 0 0" xyz="0.00 0.00 0.343"/>
  </joint>
  <joint name="link0_joint" type="revolute">
    <parent link="link0"/>
    <child link="link1"/>
    <origin rpy="-1.57079632679 0.0 0.0" xyz="0.01 0.0 0.036"/>
    <axis xyz="0.0 1.0 0.0"/>
    <limit effort="30" lower="-0.0785" upper="0.0785" velocity="1.0"/>
  </joint>
  <joint name="link1_joint" type="revolute">
    <parent link="link1"/>
    <child link="link2"/>
    <origin rpy="0.0 0.0 0.0" xyz="0.01 0.0 0.0"/>
    <axis xyz="0.0 0.0 1.00"/>
    <limit effort="30" lower="-3.1416" upper="0.00" velocity="1.0"/>
  </joint>
  <joint name="link2_joint" type="revolute">
    <parent link="link2"/>
    <child link="link3"/>
    <origin rpy="0 0 0" xyz="-0.07 0.0 0.00"/>
    <axis xyz="0.0 0.00 1.00"/>
    <limit effort="30" lower="-1.570" upper="1.570" velocity="1.0"/>
  </joint>
  <joint name="link3_joint" type="fixed">
    <parent link="link3"/>
    <child link="link4"/>
    <origin rpy="0 0 0" xyz="-0.02 0.0 0.00"/>
    <axis xyz="0.0 0.00 0.00"/>
    <limit effort="30" lower="-1.570" upper="1.570" velocity="1.0"/>
  </joint>
  <joint name="link4_joint" type="revolute">
    <parent link="link4"/>
    <child link="link5"/>
    <origin rpy="0 0 0" xyz="-0.07 0.0 0.00"/>
    <axis xyz="0.0 0.00 1.00"/>
    <limit effort="30" lower="-1.570" upper="0.00" velocity="1.0"/>
  </joint>
  <!-- ************************* -->
  <!--          CAMERAS           -->
  <!-- ************************* -->
  <joint name="camfixed" type="fixed">
    <origin rpy="0 0 0" xyz="0 0 0.625"/>
    <parent link="chassis"/>
    <child link="camera"/>
  </joint>
  <link name="camera">
    <collision>
      <origin rpy="0 0 0" xyz="0 0 0"/>
      <geometry>
        <box size="0.05 0.05 0.05"/>
      </geometry>
    </collision>
    <visual>
      <origin rpy="0 0 0" xyz="0 0 0"/>
      <geometry>
        <box size="0.05 0.05 0.05"/>
      </geometry>
      <material name="blue"/>
    </visual>
    <inertial>
      <mass value="0.1"/>
      <origin rpy="0 0 0" xyz="0 0 0"/>
      <inertia ixx="4.16666666667e-05" ixy="0" ixz="0" iyy="4.16666666667e-05" iyz="0" izz="4.16666666667e-05"/>
    </inertial>
  </link>
</robot>
