<?xml version="1.0" encoding="utf-8"?>
<!-- =================================================================================== -->
<!-- |    This document was autogenerated by xacro from twirtee.xacro                  | -->
<!-- |    EDITING THIS FILE BY HAND IS NOT RECOMMENDED                                 | -->
<!-- =================================================================================== -->
<robot name="twirtee">
  <!-- ================== -->
  <!-- (C) Eric JENN 2019 -->
  <!-- ================== -->
  <!-- To generate the URDF: xacro twirtee.xacro > twirtee.urdf -->
  <!-- Constants -->
  <!-- Modeling parameters -->
  <!-- [TODO] use actual values -->
  <material name="black">
    <color rgba="0.0 0.0 0.0 1.0"/>
  </material>
  <material name="blue">
    <color rgba="0.0 0.0 0.8 1.0"/>
  </material>
  <material name="green">
    <color rgba="0.0 0.8 0.0 1.0"/>
  </material>
  <material name="grey">
    <color rgba="0.2 0.2 0.2 1.0"/>
  </material>
  <material name="orange">
    <color rgba="1.0 0.423529411765 0.0392156862745 1.0"/>
  </material>
  <material name="brown">
    <color rgba="0.870588235294 0.811764705882 0.764705882353 1.0"/>
  </material>
  <material name="red">
    <color rgba="0.8 0.0 0.0 1.0"/>
  </material>
  <material name="white">
    <color rgba="1.0 1.0 1.0 1.0"/>
  </material>
  <!-- Put here the robot description -->
  <!-- =========================== -->
  <!-- Links and joints definition -->
  <!-- =========================== -->
  <link name="footprint"/>
  <!-- Robot's base -->
  <joint name="base_joint" type="fixed">
    <parent link="footprint"/>
    <child link="level0"/>
    <origin rpy="0 0 0" xyz="0 0 0.0665"/>
  </joint>
  <link name="level0">
    <visual>
      <geometry>
        <box size="0.3 0.2 0.003"/>
        <cylinder length="0.06" radius="0.002"/>
      </geometry>
    </visual>
  </link>
  <joint name="l0l1_joint" type="fixed">
    <parent link="level0"/>
    <child link="level1"/>
    <origin rpy="0 0 0" xyz=" 0.0 0.0 0.0615"/>
  </joint>
  <link name="level1">
    <visual>
      <origin rpy="0 0 0" xyz="0 0 0"/>
      <geometry>
        <box size="0.3 0.2 0.003"/>
      </geometry>
    </visual>
  </link>
  <joint name="l1l2_joint" type="fixed">
    <parent link="level1"/>
    <child link="level2"/>
    <origin rpy="0 0 0" xyz=" 0.0 0.0 0.0515"/>
  </joint>
  <link name="level2">
    <visual>
      <origin rpy="0 0 0" xyz="0 0 0"/>
      <geometry>
        <box size="0.3 0.2 0.003"/>
      </geometry>
    </visual>
  </link>
  <link name="left_wheel">
    <visual>
      <origin rpy="0 1.57079632679 1.57079632679" xyz="0 0 0"/>
      <geometry>
        <cylinder length="0.01" radius="0.032"/>
      </geometry>
      <material name="black"/>
    </visual>
  </link>
  <joint name="left_wheel_hinge" type="continuous">
    <parent link="level0"/>
    <child link="left_wheel"/>
    <origin rpy="0 0 0" xyz="0.1 0.105 -0.0345"/>
    <axis rpy="0 0 0" xyz="0 1 0"/>
    <limit effort="100" velocity="100"/>
    <joint_properties damping="0.0" friction="0.0"/>
  </joint>
  <link name="right_wheel">
    <visual>
      <origin rpy="0 1.57079632679 1.57079632679" xyz="0 0 0"/>
      <geometry>
        <cylinder length="0.01" radius="0.032"/>
      </geometry>
      <material name="black"/>
    </visual>
  </link>
  <joint name="right_wheel_hinge" type="continuous">
    <parent link="level0"/>
    <child link="right_wheel"/>
    <origin rpy="0 0 0" xyz="0.1 -0.105 -0.0345"/>
    <axis rpy="0 0 0" xyz="0 1 0"/>
    <limit effort="100" velocity="100"/>
    <joint_properties damping="0.0" friction="0.0"/>
  </joint>
  <!-- ========================== -->
  <!--          CAMERAS           -->
  <!-- ========================== -->
  <!-- ========================= -->
  <!--           LIDAR           -->
  <!-- ========================= -->
</robot>

