<?xml version="1.0" encoding="utf-8"?>
<!-- =================================================================================== -->
<!-- |    This document was autogenerated by xacro from twirtee.xacro                  | -->
<!-- |    EDITING THIS FILE BY HAND IS NOT RECOMMENDED                                 | -->
<!-- =================================================================================== -->
<robot name="twirtee">
  <!-- ================== -->
  <!-- (C) Eric JENN 2019 -->
  <!-- ================== -->
  <!-- Constants -->
  <!-- Modeling parameters -->
  <!-- [TODO] use actual values -->
  <!-- (C) Eric JENN 2019 -->
  <!-- For more information about Gazebo extensions, 
     see http://gazebosim.org/tutorials?tut=ros_gzplugins -->
  <!-- The materials can be found in /usr/share/gazebo-9/media/materials/ -->
  <!-- or at http://wiki.ros.org/simulator_gazebo/Tutorials/ListOfMaterials -->
  <gazebo reference="chassis">
    <visual>
      <material>
        <script>
          <uri>file://media/materials/scripts/gazebo.material</uri>
          <name>Gazebo/Pioneer2Body</name>
        </script>
      </material>
    </visual>
  </gazebo>
  <!-- ########################################### -->
  <!-- Set the collision flag for the arm          -->
  <!-- ########################################### -->
  <gazebo reference="link1">
    <selfCollide>true</selfCollide>
  </gazebo>
  <gazebo reference="link2">
    <selfCollide>true</selfCollide>
    <material>Gazebo/Green</material>
  </gazebo>
  <gazebo reference="link3">
    <selfCollide>true</selfCollide>
  </gazebo>
  <gazebo reference="link4">
    <selfCollide>true</selfCollide>
    <material>Gazebo/Green</material>
  </gazebo>
  <gazebo reference="link5">
    <selfCollide>true</selfCollide>
  </gazebo>
  <gazebo reference="finger">
    <selfCollide>true</selfCollide>
    <material>Gazebo/Red</material>
  </gazebo>
  <!-- ########################################### -->
  <!-- Define the friction coefficient for the caster "wheel" -->
  <!-- ########################################### -->
  <gazebo reference="caster_wheel">
    <mu1>0.0</mu1>
    <mu2>0.0</mu2>
    <material>Gazebo/Red</material>
  </gazebo>
  <!-- ########################################### -->
  <!--                                             -->
  <!-- ########################################### -->
  <gazebo>
    <plugin filename="libgazebo_ros_control.so" name="gazebo_ros_control">
      <robotNamespace>/twirtee</robotNamespace>
    </plugin>
  </gazebo>
  <!-- ########################################### -->
  <!-- Configure the differential drive controller -->
  <!-- The robot can be driven manually using command: 
$ rosrun turtlesim turtle_teleop_key /turtle1/cmd_vel:=/twirtee/cmd_vel -->
  <!-- ########################################### -->
  <gazebo>
    <plugin filename="libgazebo_ros_diff_drive.so" name="differential_drive_controller">
      <alwaysOn>true</alwaysOn>
      <updateRate>10</updateRate>
      <leftJoint>left_wheel_hinge</leftJoint>
      <rightJoint>right_wheel_hinge</rightJoint>
      <wheelSeparation>0.405</wheelSeparation>
      <wheelDiameter>3.64</wheelDiameter>
      <torque>20</torque>
      <commandTopic>twirtee/cmd_vel</commandTopic>
      <odometryTopic>twirtee/odom</odometryTopic>
      <odometryFrame>odom</odometryFrame>
      <robotBaseFrame>footprint</robotBaseFrame>
    </plugin>
  </gazebo>
  <!-- #################### -->
  <!-- Configure the camera -->
  <!-- #################### -->
  <gazebo reference="camera">
    <material>Gazebo/Blue</material>
    <sensor name="camera1" type="camera">
      <update_rate>30.0</update_rate>
      <camera name="head">
        <horizontal_fov>1.3962634</horizontal_fov>
        <image>
          <width>800</width>
          <height>800</height>
          <format>R8G8B8</format>
        </image>
        <clip>
          <near>0.02</near>
          <far>300</far>
        </clip>
      </camera>
      <plugin filename="libgazebo_ros_camera.so" name="camera_controller">
        <alwaysOn>true</alwaysOn>
        <updateRate>0.0</updateRate>
        <cameraName>twirtee/camera1</cameraName>
        <imageTopicName>image_raw</imageTopicName>
        <cameraInfoTopicName>camera_info</cameraInfoTopicName>
        <frameName>camera</frameName>
        <hackBaseline>0.07</hackBaseline>
        <distortionK1>0.0</distortionK1>
        <distortionK2>0.0</distortionK2>
        <distortionK3>0.0</distortionK3>
        <distortionT1>0.0</distortionT1>
        <distortionT2>0.0</distortionT2>
      </plugin>
    </sensor>
  </gazebo>
  <!-- ################### -->
  <!-- Configure the LIDAR -->
  <!-- ################### -->
  <!-- Definition of the LIDAR sensor located on top of the LIDAR link -->
  <!-- The plugin may be changed to libgazebo_ros_gpu_laser to use the GPU -->
  <gazebo reference="rplidar_top">
    <sensor name="sensor" type="ray">
      <visualize>true</visualize>
      <update_rate>30</update_rate>
      <ray>
        <scan>
          <horizontal>
            <samples>180</samples>
            <resolution>1</resolution>
            <min_angle>-3.14159265</min_angle>
            <max_angle>3.14159265</max_angle>
          </horizontal>
        </scan>
        <range>
          <min>0.2</min>
          <max>30</max>
          <resolution>0.01</resolution>
        </range>
        <noise>
          <type>gaussian</type>
          <mean>0.0</mean>
          <stddev>0.1</stddev>
        </noise>
      </ray>
      <plugin filename="libgazebo_ros_laser.so" name="gazebo_ros_head_rplidar_controller">
        <topicName>/twirtee/lidar</topicName>
        <frameName>rplidar_top</frameName>
      </plugin>
    </sensor>
  </gazebo>
  <material name="black">
    <color rgba="0.0 0.0 0.0 1.0"/>
  </material>
  <material name="blue">
    <color rgba="0.0 0.0 0.8 1.0"/>
  </material>
  <material name="green">
    <color rgba="0.0 0.8 0.0 1.0"/>
  </material>
  <material name="grey">
    <color rgba="0.2 0.2 0.2 1.0"/>
  </material>
  <material name="orange">
    <color rgba="1.0 0.423529411765 0.0392156862745 1.0"/>
  </material>
  <material name="brown">
    <color rgba="0.870588235294 0.811764705882 0.764705882353 1.0"/>
  </material>
  <material name="red">
    <color rgba="0.8 0.0 0.0 1.0"/>
  </material>
  <material name="white">
    <color rgba="1.0 1.0 1.0 1.0"/>
  </material>
  <!-- Put here the robot description -->
  <!-- =========================== -->
  <!-- Links and joints definition -->
  <!-- =========================== -->
  <link name="footprint"/>
  <!-- Robot's base -->
  <joint name="base_joint" type="fixed">
    <parent link="footprint"/>
    <child link="chassis"/>
  </joint>
  <link name="chassis">
    <collision>
      <origin rpy="0 0 0" xyz="0 0 1.82"/>
      <geometry>
        <cylinder length="0.5" radius="0.2"/>
      </geometry>
    </collision>
    <visual>
      <origin rpy="0 0 0" xyz="0 0 1.82"/>
      <geometry>
        <cylinder length="0.5" radius="0.2"/>
      </geometry>
    </visual>
    <inertial>
      <origin rpy="0 0 0" xyz="0 0 1.82"/>
      <mass value="50"/>
      <inertia ixx="1.54166666667" ixy="0" ixz="0" iyy="1.54166666667" iyz="0" izz="1.0"/>
    </inertial>
  </link>
  <joint name="fixed" type="fixed">
    <parent link="chassis"/>
    <child link="caster_wheel"/>
  </joint>
  <link name="caster_wheel">
    <collision>
      <origin rpy="0 0 0" xyz="-0.1 0 -0.15"/>
      <geometry>
        <sphere radius="0.1"/>
      </geometry>
    </collision>
    <visual>
      <origin rpy="0 0 0" xyz="-0.1 0 -0.15"/>
      <geometry>
        <sphere radius="0.1"/>
      </geometry>
      <material name="red"/>
    </visual>
    <inertial>
      <origin rpy="0 0 0" xyz="-0.1 0 -0.35"/>
      <mass value="5"/>
      <inertia ixx="0.02" ixy="0" ixz="0" iyy="0.02" iyz="0" izz="0.02"/>
    </inertial>
  </link>
  <link name="left_wheel">
    <collision>
      <origin rpy="0 1.57079632679 1.57079632679" xyz="0 0 0"/>
      <geometry>
        <cylinder length="0.005" radius="1.82"/>
      </geometry>
    </collision>
    <visual>
      <origin rpy="0 1.57079632679 1.57079632679" xyz="0 0 0"/>
      <geometry>
        <cylinder length="0.005" radius="1.82"/>
      </geometry>
      <material name="black"/>
    </visual>
    <inertial>
      <origin rpy="0 1.57079632679 1.57079632679" xyz="0 0 0"/>
      <mass value="5"/>
      <inertia ixx="4.14051041667" ixy="0" ixz="0" iyy="4.14051041667" iyz="0" izz="8.281"/>
    </inertial>
  </link>
  <!-- Define friction characteristics -->
  <gazebo reference="left_wheel">
    <mu1 value="1.0"/>
    <mu2 value="1.0"/>
    <kp value="10000000.0"/>
    <kd value="1.0"/>
    <fdir1 value="1 0 0"/>
    <material>Gazebo/Black</material>
  </gazebo>
  <joint name="left_wheel_hinge" type="continuous">
    <parent link="chassis"/>
    <child link="left_wheel"/>
    <origin rpy="0 0 0" xyz="0.15 0.2025 1.57"/>
    <axis rpy="0 0 0" xyz="0 1 0"/>
    <limit effort="100" velocity="100"/>
    <joint_properties damping="0.0" friction="0.0"/>
  </joint>
  <transmission name="left_trans">
    <type>transmission_interface/SimpleTransmission</type>
    <joint name="left_wheel_hinge">
      <hardwareInterface>hardware_interface/EffortJointInterface</hardwareInterface>
    </joint>
    <actuator name="leftMotor">
      <hardwareInterface>hardware_interface/EffortJointInterface</hardwareInterface>
      <mechanicalReduction>100</mechanicalReduction>
    </actuator>
  </transmission>
  <link name="right_wheel">
    <collision>
      <origin rpy="0 1.57079632679 1.57079632679" xyz="0 0 0"/>
      <geometry>
        <cylinder length="0.005" radius="1.82"/>
      </geometry>
    </collision>
    <visual>
      <origin rpy="0 1.57079632679 1.57079632679" xyz="0 0 0"/>
      <geometry>
        <cylinder length="0.005" radius="1.82"/>
      </geometry>
      <material name="black"/>
    </visual>
    <inertial>
      <origin rpy="0 1.57079632679 1.57079632679" xyz="0 0 0"/>
      <mass value="5"/>
      <inertia ixx="4.14051041667" ixy="0" ixz="0" iyy="4.14051041667" iyz="0" izz="8.281"/>
    </inertial>
  </link>
  <!-- Define friction characteristics -->
  <gazebo reference="right_wheel">
    <mu1 value="1.0"/>
    <mu2 value="1.0"/>
    <kp value="10000000.0"/>
    <kd value="1.0"/>
    <fdir1 value="1 0 0"/>
    <material>Gazebo/Black</material>
  </gazebo>
  <joint name="right_wheel_hinge" type="continuous">
    <parent link="chassis"/>
    <child link="right_wheel"/>
    <origin rpy="0 0 0" xyz="0.15 -0.2025 1.57"/>
    <axis rpy="0 0 0" xyz="0 1 0"/>
    <limit effort="100" velocity="100"/>
    <joint_properties damping="0.0" friction="0.0"/>
  </joint>
  <transmission name="right_trans">
    <type>transmission_interface/SimpleTransmission</type>
    <joint name="right_wheel_hinge">
      <hardwareInterface>hardware_interface/EffortJointInterface</hardwareInterface>
    </joint>
    <actuator name="rightMotor">
      <hardwareInterface>hardware_interface/EffortJointInterface</hardwareInterface>
      <mechanicalReduction>100</mechanicalReduction>
    </actuator>
  </transmission>
  <!-- Robot's arm -->
  <link name="link0">
    <visual>
      <origin rpy="0 0 0" xyz="0.0 0.0 0.0"/>
      <geometry>
        <box size="0.04 0.02 0.036"/>
      </geometry>
      <material name="green"/>
    </visual>
    <collision>
      <origin rpy="0 0 0" xyz="0.0 0.0 0.0"/>
      <geometry>
        <box size="0.04 0.02 0.036"/>
      </geometry>
    </collision>
    <visual>
      <origin rpy="0 0 0" xyz="0.01 0.0 0.022"/>
      <geometry>
        <cylinder length="0.008" radius="0.001"/>
      </geometry>
      <material name="green"/>
    </visual>
    <inertial>
      <origin rpy="0 0 0" xyz="0.0 0.0 0.0"/>
      <mass value="0.05"/>
      <inertia ixx="7.06666666667e-06" ixy="0" ixz="0" iyy="1.20666666667e-05" iyz="0" izz="1.20666666667e-05"/>
    </inertial>
  </link>
  <!-- A "transmission" defines the relation between and actuator and a joint. 
     See http://wiki.ros.org/urdf/XML/Transmission-->
  <transmission name="link0_trans">
    <type>transmission_interface/SimpleTransmission</type>
    <joint name="link0_joint">
      <hardwareInterface>hardware_interface/EffortJointInterface</hardwareInterface>
    </joint>
    <actuator name="link0_motor">
      <hardwareInterface>hardware_interface/EffortJointInterface</hardwareInterface>
      <mechanicalReduction>100</mechanicalReduction>
    </actuator>
  </transmission>
  <link name="link1">
    <visual>
      <origin rpy="0 0 0" xyz="0.0 0.0 0.0"/>
      <geometry>
        <box size="0.04 0.02 0.036"/>
      </geometry>
      <material name="green"/>
    </visual>
    <collision>
      <origin rpy="0 0 0" xyz="0.0 0.0 0.0"/>
      <geometry>
        <box size="0.04 0.02 0.036"/>
      </geometry>
    </collision>
    <visual>
      <origin rpy="0 0 0" xyz="0.01 0.0 0.022"/>
      <geometry>
        <cylinder length="0.008" radius="0.001"/>
      </geometry>
      <material name="green"/>
    </visual>
    <inertial>
      <origin rpy="0 0 0" xyz="0.0 0.0 0.0"/>
      <mass value="0.05"/>
      <inertia ixx="7.06666666667e-06" ixy="0" ixz="0" iyy="1.20666666667e-05" iyz="0" izz="1.20666666667e-05"/>
    </inertial>
  </link>
  <!-- A "transmission" defines the relation between and actuator and a joint. 
     See http://wiki.ros.org/urdf/XML/Transmission-->
  <transmission name="link1_trans">
    <type>transmission_interface/SimpleTransmission</type>
    <joint name="link1_joint">
      <hardwareInterface>hardware_interface/EffortJointInterface</hardwareInterface>
    </joint>
    <actuator name="link1_motor">
      <hardwareInterface>hardware_interface/EffortJointInterface</hardwareInterface>
      <mechanicalReduction>100</mechanicalReduction>
    </actuator>
  </transmission>
  <link name="link2">
    <visual>
      <origin rpy="0.00 0.00 0.00" xyz="-0.035 0.0 -0.018"/>
      <geometry>
        <box size="0.090  0.010 0.001"/>
      </geometry>
      <material name="red"/>
    </visual>
    <visual>
      <origin rpy="0.00 0.00 0.00" xyz="-0.035 0.00 0.018"/>
      <geometry>
        <box size="0.090 0.010 0.001"/>
      </geometry>
      <material name="red"/>
    </visual>
    <inertial>
      <mass value="0.05"/>
      <inertia ixx="0.04" ixy="0.00" ixz="0.00" iyy="0.04" iyz="0.00" izz="0.02"/>
    </inertial>
  </link>
  <link name="link3">
    <visual>
      <origin rpy="0 0 0" xyz="-0.01 0.0 0.0"/>
      <geometry>
        <box size="0.04 0.02 0.036"/>
      </geometry>
      <material name="green"/>
    </visual>
    <collision>
      <origin rpy="0 0 0" xyz="-0.01 0.0 0.0"/>
      <geometry>
        <box size="0.04 0.02 0.036"/>
      </geometry>
    </collision>
    <visual>
      <origin rpy="0 0 0" xyz="0.0 0.0 0.022"/>
      <geometry>
        <cylinder length="0.008" radius="0.001"/>
      </geometry>
      <material name="green"/>
    </visual>
    <inertial>
      <origin rpy="0 0 0" xyz="-0.01 0.0 0.0"/>
      <mass value="0.05"/>
      <inertia ixx="7.06666666667e-06" ixy="0" ixz="0" iyy="1.20666666667e-05" iyz="0" izz="1.20666666667e-05"/>
    </inertial>
  </link>
  <!-- A "transmission" defines the relation between and actuator and a joint. 
     See http://wiki.ros.org/urdf/XML/Transmission-->
  <transmission name="link3_trans">
    <type>transmission_interface/SimpleTransmission</type>
    <joint name="link3_joint">
      <hardwareInterface>hardware_interface/EffortJointInterface</hardwareInterface>
    </joint>
    <actuator name="link3_motor">
      <hardwareInterface>hardware_interface/EffortJointInterface</hardwareInterface>
      <mechanicalReduction>100</mechanicalReduction>
    </actuator>
  </transmission>
  <link name="link4">
    <visual>
      <origin rpy="0.00 0.00 0.00" xyz="-0.035 0.0 -0.018"/>
      <geometry>
        <box size="0.090  0.010 0.001"/>
      </geometry>
      <material name="red"/>
    </visual>
    <visual>
      <origin rpy="0.00 0.00 0.00" xyz="-0.035 0.00 0.018"/>
      <geometry>
        <box size="0.090 0.010 0.001"/>
      </geometry>
      <material name="red"/>
    </visual>
    <inertial>
      <mass value="0.05"/>
      <inertia ixx="0.04" ixy="0.00" ixz="0.00" iyy="0.04" iyz="0.00" izz="0.02"/>
    </inertial>
  </link>
  <link name="link5">
    <visual>
      <origin rpy="0 0 0" xyz="-0.01 0.0 0.0"/>
      <geometry>
        <box size="0.04 0.02 0.036"/>
      </geometry>
      <material name="green"/>
    </visual>
    <collision>
      <origin rpy="0 0 0" xyz="-0.01 0.0 0.0"/>
      <geometry>
        <box size="0.04 0.02 0.036"/>
      </geometry>
    </collision>
    <visual>
      <origin rpy="0 0 0" xyz="0.0 0.0 0.022"/>
      <geometry>
        <cylinder length="0.008" radius="0.001"/>
      </geometry>
      <material name="green"/>
    </visual>
    <inertial>
      <origin rpy="0 0 0" xyz="-0.01 0.0 0.0"/>
      <mass value="0.05"/>
      <inertia ixx="7.06666666667e-06" ixy="0" ixz="0" iyy="1.20666666667e-05" iyz="0" izz="1.20666666667e-05"/>
    </inertial>
  </link>
  <!-- A "transmission" defines the relation between and actuator and a joint. 
     See http://wiki.ros.org/urdf/XML/Transmission-->
  <transmission name="link5_trans">
    <type>transmission_interface/SimpleTransmission</type>
    <joint name="link5_joint">
      <hardwareInterface>hardware_interface/EffortJointInterface</hardwareInterface>
    </joint>
    <actuator name="link5_motor">
      <hardwareInterface>hardware_interface/EffortJointInterface</hardwareInterface>
      <mechanicalReduction>100</mechanicalReduction>
    </actuator>
  </transmission>
  <link name="finger">
    <visual>
      <origin rpy="0 1.57079632679 0 " xyz="-0.03 0.0 0.0 "/>
      <geometry>
        <cylinder length="0.05" radius="0.001"/>
      </geometry>
    </visual>
    <collision>
      <origin rpy="0 1.57079632679 0 " xyz="-0.03 0.0 0.0 "/>
      <geometry>
        <cylinder length="0.05" radius="0.001"/>
      </geometry>
    </collision>
    <inertial>
      <origin rpy="0 1.57079632679 0 " xyz="-0.03 0.0 0.0 "/>
      <mass value="0.01"/>
      <inertia ixx="2.08583333333e-06" ixy="0" ixz="0" iyy="2.08583333333e-06" iyz="0" izz="5e-09"/>
    </inertial>
  </link>
  <joint name="chassis_arm" type="fixed">
    <parent link="chassis"/>
    <child link="link0"/>
    <origin rpy="0 0 0" xyz="0.00 0.00 2.088"/>
  </joint>
  <joint name="link0_joint" type="revolute">
    <parent link="link0"/>
    <child link="link1"/>
    <origin rpy="-1.57079632679 0.0 0.0" xyz="0.01 0.0 0.036"/>
    <axis xyz="0.0 1.0 0.0"/>
    <limit effort="30" lower="-1.57079632679" upper="1.57079632679" velocity="1.0"/>
  </joint>
  <joint name="link1_joint" type="revolute">
    <parent link="link1"/>
    <child link="link2"/>
    <origin rpy="0.0 0.0 0.0" xyz="0.01 0.0 0.0"/>
    <axis xyz="0.0 0.0 1.00"/>
    <limit effort="30" lower="-1.57079632679" upper="1.57079632679" velocity="1.0"/>
  </joint>
  <joint name="link3_joint" type="revolute">
    <parent link="link2"/>
    <child link="link3"/>
    <origin rpy="0 0 0" xyz="-0.07 0.0 0.00"/>
    <axis xyz="0.0 0.00 1.00"/>
    <limit effort="30" lower="-1.57079632679" upper="1.57079632679" velocity="1.0"/>
  </joint>
  <joint name="link4_joint" type="fixed">
    <parent link="link3"/>
    <child link="link4"/>
    <origin rpy="0 0 0" xyz="-0.02 0.0 0.00"/>
  </joint>
  <joint name="link5_joint" type="revolute">
    <parent link="link4"/>
    <child link="link5"/>
    <origin rpy="0 0 0" xyz="-0.07 0.0 0.00"/>
    <axis xyz="0.0 0.00 1.00"/>
    <limit effort="30" lower="-1.57079632679" upper="1.57079632679" velocity="1.0"/>
  </joint>
  <joint name="link6_joint" type="fixed">
    <parent link="link5"/>
    <child link="camera"/>
    <origin rpy="1.57079632679 3.14159265359 0.0" xyz="-0.01 -0.02 0.0"/>
  </joint>
  <joint name="link7_joint" type="fixed">
    <parent link="link5"/>
    <child link="finger"/>
    <origin rpy="0.0 0.0 0.0" xyz="0.0 0.0 0.0"/>
  </joint>
  <!-- ========================== -->
  <!--          CAMERAS           -->
  <!-- ========================== -->
  <link name="camera">
    <collision>
      <origin rpy="0 0 0" xyz="0.0 0.0 0.0"/>
      <geometry>
        <box size="0.02 0.02 0.02"/>
      </geometry>
    </collision>
    <visual>
      <origin rpy="0 0 0" xyz="0.0 0.0 0.0"/>
      <geometry>
        <box size="0.02 0.02 0.02"/>
      </geometry>
      <material name="blue"/>
    </visual>
    <inertial>
      <mass value="0.5"/>
      <origin rpy="0 0 0" xyz="0 0 0"/>
      <inertia ixx="3.33333333333e-05" ixy="0" ixz="0" iyy="3.33333333333e-05" iyz="0" izz="3.33333333333e-05"/>
    </inertial>
  </link>
  <!-- ========================= -->
  <!--           LIDAR           -->
  <!-- ========================= -->
  <joint name="chassis_lidar" type="fixed">
    <parent link="chassis"/>
    <child link="rplidar_base"/>
    <origin rpy="0 0 0" xyz="0.1 0 2.099335"/>
  </joint>
  <link name="rplidar_base">
    <collision>
      <origin rpy="0 0 0" xyz="0 0 0"/>
      <geometry>
        <cylinder length=".05867" radius="0.04267"/>
      </geometry>
    </collision>
    <visual>
      <origin rpy="0 0 0" xyz="0 0 0"/>
      <geometry>
        <cylinder length=".05867" radius="0.04267"/>
      </geometry>
    </visual>
    <inertial>
      <mass value="0.01"/>
      <origin rpy="0 0 0" xyz="0 0 0"/>
      <inertia ixx="7.42029633333e-06" ixy="0" ixz="0" iyy="7.42029633333e-06" iyz="0" izz="9.1036445e-06"/>
    </inertial>
  </link>
  <joint name="rplidar_base_top" type="revolute">
    <parent link="rplidar_base"/>
    <child link="rplidar_top"/>
    <origin rpy="0 0 0" xyz="0.0 0.0 0.029335"/>
    <axis xyz="0.0 0.0 1.0"/>
    <limit effort="30" lower="-3.14159265359" upper="3.14159265359" velocity="1.0"/>
    <dynamics damping="1.0" friction="100.0"/>
  </joint>
  <link name="rplidar_top">
    <collision>
      <origin rpy="0 0 0" xyz="0 0 0"/>
      <geometry>
        <cylinder length="0.07357" radius="0.04267"/>
      </geometry>
    </collision>
    <visual>
      <origin rpy="0 0 0" xyz="0 0 0"/>
      <geometry>
        <cylinder length="0.07357" radius="0.04267"/>
      </geometry>
    </visual>
    <inertial>
      <mass value="0.01"/>
      <origin rpy="0 0 0" xyz="0 0 0"/>
      <inertia ixx="9.06227633333e-05" ixy="0" ixz="0" iyy="9.06227633333e-05" iyz="0" izz="9.1036445e-05"/>
    </inertial>
  </link>
  <!-- The RPLIDAR is controlled in order for the TF to be published (otherwise Rviz will indicate an error.  -->
  <transmission name="rplidar">
    <type>transmission_interface/SimpleTransmission</type>
    <joint name="rplidar_base_top">
      <hardwareInterface>hardware_interface/EffortJointInterface</hardwareInterface>
    </joint>
    <actuator name="rplidar_motor">
      <hardwareInterface>hardware_interface/EffortJointInterface</hardwareInterface>
      <mechanicalReduction>1</mechanicalReduction>
    </actuator>
  </transmission>
</robot>

